Workbook

Sheet Summary
A1: Where is Northwind wasting the most time — and what to automate first?
A2: Live view of the 'Workflows' tab, ordered by priority rank (criticality first, hours as tiebreaker). Scope: Q1 2026 tickets; Slack/notes Apr 21 – Jun 17, 2026.
A4: Rank | B4: Workflow | C4: Hours / qtr | D4: Low | E4: High | F4: Criticality (of 15) | G4: Measured or claimed | H4: Automatable?
A5: 1 | B5: =IFERROR(INDEX(Workflows!$C$3:$C$10,MATCH($A5,Workflows!$W$3:$W$10,0))&"","") -> Brand-deal revenue reconciliation (CRM ↔ invoicing ↔ payout tracker) | C5: =IFERROR(IF(INDEX(Workflows!$I$3:$I$10,MATCH($A5,Workflows!$W$3:$W$10,0))="","—",INDEX(Workflows!$I$3:$I$10,MATCH($A5,Workflows!$W$3:$W$10,0))),"") -> 72 | D5: =IFERROR(IF(INDEX(Workflows!$J$3:$J$10,MATCH($A5,Workflows!$W$3:$W$10,0))="","—",INDEX(Workflows!$J$3:$J$10,MATCH($A5,Workflows!$W$3:$W$10,0))),"") -> 45 | E5: =IFERROR(IF(INDEX(Workflows!$K$3:$K$10,MATCH($A5,Workflows!$W$3:$W$10,0))="","—",INDEX(Workflows!$K$3:$K$10,MATCH($A5,Workflows!$W$3:$W$10,0))),"") -> 84 | F5: =IFERROR(IF(INDEX(Workflows!$S$3:$S$10,MATCH($A5,Workflows!$W$3:$W$10,0))="","—",INDEX(Workflows!$S$3:$S$10,MATCH($A5,Workflows!$W$3:$W$10,0))),"") -> 15 | G5: =IFERROR(INDEX(Workflows!$L$3:$L$10,MATCH($A5,Workflows!$W$3:$W$10,0))&"","") -> Claimed — same '~3 days' in Slack, finance review and leadership minutes | H5: =IFERROR(INDEX(Workflows!$T$3:$T$10,MATCH($A5,Workflows!$W$3:$W$10,0))&"","") -> Yes — 3-way match
A6: 2 | B6: =IFERROR(INDEX(Workflows!$C$3:$C$10,MATCH($A6,Workflows!$W$3:$W$10,0))&"","") -> Reconciling the 'active creators' number (1,210 vs 1,840) for decks | C6: =IFERROR(IF(INDEX(Workflows!$I$3:$I$10,MATCH($A6,Workflows!$W$3:$W$10,0))="","—",INDEX(Workflows!$I$3:$I$10,MATCH($A6,Workflows!$W$3:$W$10,0))),"") -> — | D6: =IFERROR(IF(INDEX(Workflows!$J$3:$J$10,MATCH($A6,Workflows!$W$3:$W$10,0))="","—",INDEX(Workflows!$J$3:$J$10,MATCH($A6,Workflows!$W$3:$W$10,0))),"") -> — | E6: =IFERROR(IF(INDEX(Workflows!$K$3:$K$10,MATCH($A6,Workflows!$W$3:$W$10,0))="","—",INDEX(Workflows!$K$3:$K$10,MATCH($A6,Workflows!$W$3:$W$10,0))),"") -> — | F6: =IFERROR(IF(INDEX(Workflows!$S$3:$S$10,MATCH($A6,Workflows!$W$3:$W$10,0))="","—",INDEX(Workflows!$S$3:$S$10,MATCH($A6,Workflows!$W$3:$W$10,0))),"") -> 11 | G6: =IFERROR(INDEX(Workflows!$L$3:$L$10,MATCH($A6,Workflows!$W$3:$W$10,0))&"","") -> Not quantified | H6: =IFERROR(INDEX(Workflows!$T$3:$T$10,MATCH($A6,Workflows!$W$3:$W$10,0))&"","") -> No — a definition decision, not automation
A7: 3 | B7: =IFERROR(INDEX(Workflows!$C$3:$C$10,MATCH($A7,Workflows!$W$3:$W$10,0))&"","") -> Tax-form chasing (W-9 / W-8) | C7: =IFERROR(IF(INDEX(Workflows!$I$3:$I$10,MATCH($A7,Workflows!$W$3:$W$10,0))="","—",INDEX(Workflows!$I$3:$I$10,MATCH($A7,Workflows!$W$3:$W$10,0))),"") -> 25.916667 | D7: =IFERROR(IF(INDEX(Workflows!$J$3:$J$10,MATCH($A7,Workflows!$W$3:$W$10,0))="","—",INDEX(Workflows!$J$3:$J$10,MATCH($A7,Workflows!$W$3:$W$10,0))),"") -> 25.916667 | E7: =IFERROR(IF(INDEX(Workflows!$K$3:$K$10,MATCH($A7,Workflows!$W$3:$W$10,0))="","—",INDEX(Workflows!$K$3:$K$10,MATCH($A7,Workflows!$W$3:$W$10,0))),"") -> 51.833333 | F7: =IFERROR(IF(INDEX(Workflows!$S$3:$S$10,MATCH($A7,Workflows!$W$3:$W$10,0))="","—",INDEX(Workflows!$S$3:$S$10,MATCH($A7,Workflows!$W$3:$W$10,0))),"") -> 9 | G7: =IFERROR(INDEX(Workflows!$L$3:$L$10,MATCH($A7,Workflows!$W$3:$W$10,0))&"","") -> Measured (ticket log) | H7: =IFERROR(INDEX(Workflows!$T$3:$T$10,MATCH($A7,Workflows!$W$3:$W$10,0))&"","") -> Yes — e-sign + reminders
A8: 4 | B8: =IFERROR(INDEX(Workflows!$C$3:$C$10,MATCH($A8,Workflows!$W$3:$W$10,0))&"","") -> Post-production bottleneck (editing, re-exports) | C8: =IFERROR(IF(INDEX(Workflows!$I$3:$I$10,MATCH($A8,Workflows!$W$3:$W$10,0))="","—",INDEX(Workflows!$I$3:$I$10,MATCH($A8,Workflows!$W$3:$W$10,0))),"") -> — | D8: =IFERROR(IF(INDEX(Workflows!$J$3:$J$10,MATCH($A8,Workflows!$W$3:$W$10,0))="","—",INDEX(Workflows!$J$3:$J$10,MATCH($A8,Workflows!$W$3:$W$10,0))),"") -> — | E8: =IFERROR(IF(INDEX(Workflows!$K$3:$K$10,MATCH($A8,Workflows!$W$3:$W$10,0))="","—",INDEX(Workflows!$K$3:$K$10,MATCH($A8,Workflows!$W$3:$W$10,0))),"") -> — | F8: =IFERROR(IF(INDEX(Workflows!$S$3:$S$10,MATCH($A8,Workflows!$W$3:$W$10,0))="","—",INDEX(Workflows!$S$3:$S$10,MATCH($A8,Workflows!$W$3:$W$10,0))),"") -> 9 | G8: =IFERROR(INDEX(Workflows!$L$3:$L$10,MATCH($A8,Workflows!$W$3:$W$10,0))&"","") -> Not quantified | H8: =IFERROR(INDEX(Workflows!$T$3:$T$10,MATCH($A8,Workflows!$W$3:$W$10,0))&"","") -> Partly
A9: 5 | B9: =IFERROR(INDEX(Workflows!$C$3:$C$10,MATCH($A9,Workflows!$W$3:$W$10,0))&"","") -> Vendor / SaaS hygiene (renewal calendar, Salesforce check, EUR, Amplitude invoice) | C9: =IFERROR(IF(INDEX(Workflows!$I$3:$I$10,MATCH($A9,Workflows!$W$3:$W$10,0))="","—",INDEX(Workflows!$I$3:$I$10,MATCH($A9,Workflows!$W$3:$W$10,0))),"") -> — | D9: =IFERROR(IF(INDEX(Workflows!$J$3:$J$10,MATCH($A9,Workflows!$W$3:$W$10,0))="","—",INDEX(Workflows!$J$3:$J$10,MATCH($A9,Workflows!$W$3:$W$10,0))),"") -> — | E9: =IFERROR(IF(INDEX(Workflows!$K$3:$K$10,MATCH($A9,Workflows!$W$3:$W$10,0))="","—",INDEX(Workflows!$K$3:$K$10,MATCH($A9,Workflows!$W$3:$W$10,0))),"") -> — | F9: =IFERROR(IF(INDEX(Workflows!$S$3:$S$10,MATCH($A9,Workflows!$W$3:$W$10,0))="","—",INDEX(Workflows!$S$3:$S$10,MATCH($A9,Workflows!$W$3:$W$10,0))),"") -> 9 | G9: =IFERROR(INDEX(Workflows!$L$3:$L$10,MATCH($A9,Workflows!$W$3:$W$10,0))&"","") -> Not quantified | H9: =IFERROR(INDEX(Workflows!$T$3:$T$10,MATCH($A9,Workflows!$W$3:$W$10,0))&"","") -> Yes — vendor calendar + checks
A10: 6 | B10: =IFERROR(INDEX(Workflows!$C$3:$C$10,MATCH($A10,Workflows!$W$3:$W$10,0))&"","") -> Payout questions ('where's my payout') | C10: =IFERROR(IF(INDEX(Workflows!$I$3:$I$10,MATCH($A10,Workflows!$W$3:$W$10,0))="","—",INDEX(Workflows!$I$3:$I$10,MATCH($A10,Workflows!$W$3:$W$10,0))),"") -> 14.583333 | D10: =IFERROR(IF(INDEX(Workflows!$J$3:$J$10,MATCH($A10,Workflows!$W$3:$W$10,0))="","—",INDEX(Workflows!$J$3:$J$10,MATCH($A10,Workflows!$W$3:$W$10,0))),"") -> 14.583333 | E10: =IFERROR(IF(INDEX(Workflows!$K$3:$K$10,MATCH($A10,Workflows!$W$3:$W$10,0))="","—",INDEX(Workflows!$K$3:$K$10,MATCH($A10,Workflows!$W$3:$W$10,0))),"") -> 29.166667 | F10: =IFERROR(IF(INDEX(Workflows!$S$3:$S$10,MATCH($A10,Workflows!$W$3:$W$10,0))="","—",INDEX(Workflows!$S$3:$S$10,MATCH($A10,Workflows!$W$3:$W$10,0))),"") -> 8 | G10: =IFERROR(INDEX(Workflows!$L$3:$L$10,MATCH($A10,Workflows!$W$3:$W$10,0))&"","") -> Measured (ticket log) | H10: =IFERROR(INDEX(Workflows!$T$3:$T$10,MATCH($A10,Workflows!$W$3:$W$10,0))&"","") -> Partly — needs payout tracker
A11: 7 | B11: =IFERROR(INDEX(Workflows!$C$3:$C$10,MATCH($A11,Workflows!$W$3:$W$10,0))&"","") -> Thumbnail re-uploads after publish | C11: =IFERROR(IF(INDEX(Workflows!$I$3:$I$10,MATCH($A11,Workflows!$W$3:$W$10,0))="","—",INDEX(Workflows!$I$3:$I$10,MATCH($A11,Workflows!$W$3:$W$10,0))),"") -> 22.75 | D11: =IFERROR(IF(INDEX(Workflows!$J$3:$J$10,MATCH($A11,Workflows!$W$3:$W$10,0))="","—",INDEX(Workflows!$J$3:$J$10,MATCH($A11,Workflows!$W$3:$W$10,0))),"") -> 22.75 | E11: =IFERROR(IF(INDEX(Workflows!$K$3:$K$10,MATCH($A11,Workflows!$W$3:$W$10,0))="","—",INDEX(Workflows!$K$3:$K$10,MATCH($A11,Workflows!$W$3:$W$10,0))),"") -> 45.5 | F11: =IFERROR(IF(INDEX(Workflows!$S$3:$S$10,MATCH($A11,Workflows!$W$3:$W$10,0))="","—",INDEX(Workflows!$S$3:$S$10,MATCH($A11,Workflows!$W$3:$W$10,0))),"") -> 6 | G11: =IFERROR(INDEX(Workflows!$L$3:$L$10,MATCH($A11,Workflows!$W$3:$W$10,0))&"","") -> Measured (ticket log) | H11: =IFERROR(INDEX(Workflows!$T$3:$T$10,MATCH($A11,Workflows!$W$3:$W$10,0))&"","") -> Yes — self-serve swap
A12: 8 | B12: =IFERROR(INDEX(Workflows!$C$3:$C$10,MATCH($A12,Workflows!$W$3:$W$10,0))&"","") -> Other support (login, account access, takedowns) | C12: =IFERROR(IF(INDEX(Workflows!$I$3:$I$10,MATCH($A12,Workflows!$W$3:$W$10,0))="","—",INDEX(Workflows!$I$3:$I$10,MATCH($A12,Workflows!$W$3:$W$10,0))),"") -> 7.25 | D12: =IFERROR(IF(INDEX(Workflows!$J$3:$J$10,MATCH($A12,Workflows!$W$3:$W$10,0))="","—",INDEX(Workflows!$J$3:$J$10,MATCH($A12,Workflows!$W$3:$W$10,0))),"") -> 7.25 | E12: =IFERROR(IF(INDEX(Workflows!$K$3:$K$10,MATCH($A12,Workflows!$W$3:$W$10,0))="","—",INDEX(Workflows!$K$3:$K$10,MATCH($A12,Workflows!$W$3:$W$10,0))),"") -> 14.5 | F12: =IFERROR(IF(INDEX(Workflows!$S$3:$S$10,MATCH($A12,Workflows!$W$3:$W$10,0))="","—",INDEX(Workflows!$S$3:$S$10,MATCH($A12,Workflows!$W$3:$W$10,0))),"") -> 5 | G12: =IFERROR(INDEX(Workflows!$L$3:$L$10,MATCH($A12,Workflows!$W$3:$W$10,0))&"","") -> Measured (ticket log) | H12: =IFERROR(INDEX(Workflows!$T$3:$T$10,MATCH($A12,Workflows!$W$3:$W$10,0))&"","") -> No — security / legal judgment
A14: Answer
A15: Two workflows tie on hours: brand-deal revenue reconciliation (~72 h/qtr, claimed; bounds 45–84) and creator support (70.5 h/qtr, measured). Automate the reconciliation first: it scores 15/15 on criticality — 80% of revenue, board-level numbers, every month-end close, one person, and getting worse with volume.
A16: Catch: none of its three inputs (CRM export, invoicing sheet, payout tracker) is in the bundle — see 'Missing data'. Scope is in Analysis/automation/RECON_SCOPE.md. The support automation (tax forms + thumbnails) is what runs on this data today.
A17: Confidence: Medium on the ranking (recon time is self-reported); High that W1 and support are the two largest — nothing else has a time figure.
A18: Colour key — Workflows: green = measured, amber = claimed, grey = not quantified, red = data to build it is missing. Blue numbers are inputs.

Sheet Workflows
A1: Every workflow the bundle shows manual effort piling up on. Blue = typed input with source; black = formula. Criticality reasons are in the 'why' columns; definitions on 'Criticality rubric'.
A2: ID | B2: Function | C2: Workflow | D2: Who does it | E2: Time basis | F2: Qty | G2: Unit | H2: Hours/day (assump.) | I2: Hours / quarter | J2: Low h/qtr | K2: High h/qtr | L2: Measured or claimed | M2: # sources | N2: Money exposure | O2: Trust in the numbers | P2: Deadline pressure | Q2: Key-person risk | R2: Growth | S2: Criticality (of 15) | T2: Automatable? | U2: Data in bundle to build it? | V2: Sort key | W2: Priority rank | X2: Why: Money exposure | Y2: Why: Trust in the numbers | Z2: Why: Deadline pressure | AA2: Why: Key-person risk | AB2: Why: Growth
A3: W1 | B3: Finance | C3: Brand-deal revenue reconciliation (CRM ↔ invoicing ↔ payout tracker) | D3: Maya Fortin (Finance Analyst) | E3: '~3 full days' per month-end (slack L108, L158; finance_review L11) | F3: 3 | G3: days/month | H3: 8 | I3: =F3*H3*3 -> 72 | J3: =2.5*6*3 -> 45 | K3: =3.5*8*3 -> 84 | L3: Claimed — same '~3 days' in Slack, finance review and leadership minutes | M3: =COUNTIFS(Evidence!$A$3:$A$52,A3) -> 13 | N3: 3 | O3: 3 | P3: 3 | Q3: 3 | R3: 3 | S3: =SUM(N3:R3) -> 15 | T3: Yes — 3-way match | U3: No — none of the 3 exports is in the bundle | V3: =S3*1000+N(I3)+(100-ROW())/10000 -> 15072.01 | W3: =RANK(V3,$V$3:$V$10) -> 1 | X3: Brand partnerships = $4.2M of $5.25M revenue (80%) — pnl L2, L5 | Y3: Revenue figures for the board 'never tie out first pass' — finance_review L12; slack L114 | Z3: Every month-end close — slack L108, L158; finance_review L11 | AA3: Only Maya does it — slack L94, L108 | AB3: 'only going to get worse as brand-partnership volume grows' — finance_review L13
A4: W2 | B4: Ops / support | C4: Tax-form chasing (W-9 / W-8) | D4: Ops Support (Liam Doyle's team) | E4: Sum of Handle_Minutes, Q1 tickets (Tax form (W-9/W-8)) | I4: =(SUMIFS('Tickets (raw)'!$G$3:$G$142,'Tickets (raw)'!$D$3:$D$142,"Tax form (W-9/W-8)"))/60 -> 25.916667 | J4: =I4 -> 25.916667 | K4: =I4*2 -> 51.833333 | L4: Measured (ticket log) | M4: =COUNTIFS(Evidence!$A$3:$A$52,A4) -> 4 | N4: 2 | O4: 1 | P4: 2 | Q4: 2 | R4: 2 | S4: =SUM(N4:R4) -> 9 | T4: Yes — e-sign + reminders | U4: Yes — tickets | V4: =S4*1000+N(I4)+(100-ROW())/10000 -> 9025.9263 | W4: =RANK(V4,$V$3:$V$10) -> 3 | X4: Tied to creator onboarding/payouts — slack L171 (link to payout eligibility not stated in data) | Y4: Doesn't feed leadership numbers | Z4: Recurs with onboarding and 'tax form season' — slack L201 | AA4: Ops Support team — tickets Assigned_To | AB4: Grows with new creators, incl. international (W-8) — slack L171, L201
A5: W3 | B5: Ops / support + Content | C5: Thumbnail re-uploads after publish | D5: Ops Support + Post-production | E5: Sum of Handle_Minutes, Q1 tickets (Thumbnail re-upload) | I5: =(SUMIFS('Tickets (raw)'!$G$3:$G$142,'Tickets (raw)'!$D$3:$D$142,"Thumbnail re-upload"))/60 -> 22.75 | J5: =I5 -> 22.75 | K5: =I5*2 -> 45.5 | L5: Measured (ticket log) | M5: =COUNTIFS(Evidence!$A$3:$A$52,A5) -> 4 | N5: 1 | O5: 1 | P5: 1 | Q5: 1 | R5: 2 | S5: =SUM(N5:R5) -> 6 | T5: Yes — self-serve swap | U5: Yes — tickets | V5: =S5*1000+N(I5)+(100-ROW())/10000 -> 6022.7595 | W5: =RANK(V5,$V$3:$V$10) -> 7 | X5: 'Low dollar value per ticket' — slack L196 | Y5: Doesn't feed leadership numbers | Z5: Ad hoc, creator-initiated — slack L165 | AA5: Shared between Ops and Post — slack L165, L168 | AB5: 'piling up', '#47 this week' — slack L165, L193
A6: W4 | B6: Ops / support | C6: Payout questions ('where's my payout') | D6: Ops Support | E6: Sum of Handle_Minutes, Q1 tickets (Payout question) | I6: =(SUMIFS('Tickets (raw)'!$G$3:$G$142,'Tickets (raw)'!$D$3:$D$142,"Payout question"))/60 -> 14.583333 | J6: =I6 -> 14.583333 | K6: =I6*2 -> 29.166667 | L6: Measured (ticket log) | M6: =COUNTIFS(Evidence!$A$3:$A$52,A6) -> 3 | N6: 2 | O6: 2 | P6: 1 | Q6: 1 | R6: 2 | S6: =SUM(N6:R6) -> 8 | T6: Partly — needs payout tracker | U6: Partly — tickets yes, payout tracker no | V6: =S6*1000+N(I6)+(100-ROW())/10000 -> 8014.5927 | W6: =RANK(V6,$V$3:$V$10) -> 6 | X6: Creator payouts; processing fees $31k/qtr — pnl L34 | Y6: Payout tracker is one of the 3 sources that drift — slack L100 | Z6: Ad hoc | AA6: Ops Support team | AB6: Grows with creators — slack L176
A7: W5 | B7: Ops / support | C7: Other support (login, account access, takedowns) | D7: Ops Support | E7: Sum of Handle_Minutes, Q1 tickets (Login issue, Account access, Content takedown) | I7: =(SUMIFS('Tickets (raw)'!$G$3:$G$142,'Tickets (raw)'!$D$3:$D$142,"Login issue")+SUMIFS('Tickets (raw)'!$G$3:$G$142,'Tickets (raw)'!$D$3:$D$142,"Account access")+SUMIFS('Tickets (raw)'!$G$3:$G$142,'Tickets (raw)'!$D$3:$D$142,"Content takedown"))/60 -> 7.25 | J7: =I7 -> 7.25 | K7: =I7*2 -> 14.5 | L7: Measured (ticket log) | M7: =COUNTIFS(Evidence!$A$3:$A$52,A7) -> 0 | N7: 1 | O7: 1 | P7: 1 | Q7: 1 | R7: 1 | S7: =SUM(N7:R7) -> 5 | T7: No — security / legal judgment | U7: Yes — tickets | V7: =S7*1000+N(I7)+(100-ROW())/10000 -> 5007.2593 | W7: =RANK(V7,$V$3:$V$10) -> 8 | X7: Small | Y7: No | Z7: Ad hoc | AA7: Team | AB7: Flat (Q1 data)
A8: W6 | B8: Data + Finance | C8: Reconciling the 'active creators' number (1,210 vs 1,840) for decks | D8: Ben Okoro, Maya Fortin, Priya Raman | E8: No time figure anywhere in the bundle | L8: Not quantified | M8: =COUNTIFS(Evidence!$A$3:$A$52,A8) -> 11 | N8: 2 | O8: 3 | P8: 3 | Q8: 2 | R8: 1 | S8: =SUM(N8:R8) -> 11 | T8: No — a definition decision, not automation | U8: Yes — but it's a decision | V8: =S8*1000+N(I8)+(100-ROW())/10000 -> 11000.009 | W8: =RANK(V8,$V$3:$V$10) -> 2 | X8: Per-creator economics for the board built on it — finance_review L18 | Y8: Two numbers in board materials — data_review L18; slack L56 | Z8: Board update deadline — data_review L41; leadership L31 | AA8: Ben + Maya/Priya — leadership L31 | AB8: Flat
A9: W7 | B9: Content | C9: Post-production bottleneck (editing, re-exports) | D9: Yuki Tanaka's post team | E9: No time figure anywhere in the bundle | L9: Not quantified | M9: =COUNTIFS(Evidence!$A$3:$A$52,A9) -> 4 | N9: 2 | O9: 1 | P9: 2 | Q9: 2 | R9: 2 | S9: =SUM(N9:R9) -> 9 | T9: Partly | U9: No — no throughput data | V9: =S9*1000+N(I9)+(100-ROW())/10000 -> 9000.0091 | W9: =RANK(V9,$V$3:$V$10) -> 4 | X9: Contractor/freelance production $410k/qtr — pnl L8 (link to bottleneck not stated) | Y9: No | Z9: Show schedules — slack L34 | AA9: Post team | AB9: Wants another editor — slack L250
A10: W8 | B10: Finance | C10: Vendor / SaaS hygiene (renewal calendar, Salesforce check, EUR, Amplitude invoice) | D10: Maya Fortin | E10: No time figure anywhere in the bundle | L10: Not quantified | M10: =COUNTIFS(Evidence!$A$3:$A$52,A10) -> 7 | N10: 1 | O10: 2 | P10: 2 | Q10: 3 | R10: 1 | S10: =SUM(N10:R10) -> 9 | T10: Yes — vendor calendar + checks | U10: Partly — P&L only, no invoices | V10: =S10*1000+N(I10)+(100-ROW())/10000 -> 9000.009 | W10: =RANK(V10,$V$3:$V$10) -> 5 | X10: SaaS $81k/qtr; $7.5k possible duplicate — pnl L24, L12–L13 | Y10: SaaS line went to the board cut — slack L42, L45 | Z10: Renewals 'inside the next two quarters' — finance_review L24 | AA10: All on Maya — finance_review L36–L39 | AB10: Flat
A12: Totals (quantified workflows) | I12: =SUM(I3:I10) -> 142.5 | J12: =SUM(J3:J10) -> 115.5 | K12: =SUM(K3:K10) -> 225

Sheet Criticality rubric
A1: Business criticality — five dimensions, each scored 1–3 (max 15). Every score on 'Workflows' cites its reason.
A2: Dimension | B2: Question | C2: 1 | D2: 2 | E2: 3
A3: Money exposure | B3: How much revenue or spend flows through it | C3: 1 = little / indirect | D3: 2 = creator payouts, cost lines, per-creator economics | E3: 3 = core revenue (brand partnerships)
A4: Trust in the numbers | B4: Do errors reach leadership / board numbers? | C4: 1 = no | D4: 2 = internal reporting | E4: 3 = board-level figures
A5: Deadline pressure | B5: Is it on a hard, recurring deadline? | C5: 1 = ad hoc | D5: 2 = recurring, soft deadline | E5: 3 = month-end close / board
A6: Key-person risk | B6: Does it depend on one person? | C6: 1 = shared team | D6: 2 = small team | E6: 3 = one named person
A7: Growth | B7: Does it get worse as the business grows? | C7: 1 = flat | D7: 2 = grows with creators | E7: 3 = explicitly flagged as getting worse
A9: Priority rule: rank by criticality score; ties broken by hours per quarter (sort key = score × 1000 + hours). Hours alone would rank W1 and support as a tie.

Sheet Evidence
A1: Every line used, quoted verbatim from its file. 'Supports' is my one-line reading.
A2: Workflow | B2: File | C2: Line | D2: Who | E2: Date | F2: Raw text (verbatim) | G2: Supports
A3: W1 | B3: slack_export.md | C3: 97 | D3: Maya Fortin | E3: 46134 | F3: Already in it. Friendly reminder that the brand-deal revenue recon is the thing that eats my life every month — three sources that never agree on the first pass. | G3: Recon 'eats my life every month' — three sources never agree first pass
A4: W1 | B4: slack_export.md | C4: 100 | D4: Maya Fortin | E4: 46134 | F4: For the record the three are: the CRM export (what Sales says closed), the invoicing sheet (what we billed), and the payout tracker (what creators actually got paid against deals). They drift every single month. | G4: Names the 3 sources: CRM export, invoicing sheet, payout tracker; 'drift every single month'
A5: W1 | B5: slack_export.md | C5: 108 | D5: Maya Fortin | E5: 46144 | F5: Closing out April. The brand-deal recon took me basically three full days again. CRM said one set of deals closed, invoicing had a different total, payout tracker had a third. Tied out eventually but it's the same dance every month-end. ~3 days, every time. | G5: April recon took ~3 full days; 'same dance every month-end'
A6: W1 | B6: slack_export.md | C6: 111 | D6: Priya Raman | E6: 46144 | F6: That's genuinely the biggest recurring time sink in finance right now. Tabling it as something we should fix properly, not band-aid. | G6: CFO: 'biggest recurring time sink in finance'
A7: W1 | B7: slack_export.md | C7: 114 | D7: Maya Fortin | E7: 46144 | F7: Please. If we automated the three-way match I'd get three days a month back and the numbers would actually be trustworthy on the first pass. | G7: Automating the 3-way match = 3 days/month back + trustworthy first pass
A8: W1 | B8: slack_export.md | C8: 158 | D8: Maya Fortin | E8: 46186 | F8: May close done. Same brand-deal recon grind — ~3 days. Broken record, I know. Whenever we prioritize automation, that's my vote for #1. | G8: May close: ~3 days again; Maya's vote for automation #1
A9: W1 | B9: meeting_notes/finance_review_2026-05-28.md | C9: 11 | D9: minutes (Maya Fortin) | E9: 46170 | F9: - April close landed on time, but the brand-deal revenue reconciliation was again the long pole. Maya flagged it took ~3 full days this cycle (same as the last few months). | G9: ~3 full days this cycle, same as last few months
A10: W1 | B10: meeting_notes/finance_review_2026-05-28.md | C10: 12 | D10: minutes (Maya Fortin) | E10: 46170 | F10: - The recon spans three systems that never agree on the first pass: the **CRM deal export**, the **invoicing sheet**, and the **payout tracker**. Deal amounts, close dates, and payout splits drift between all three, so every month is a manual line-by-line tie-out. | G10: Amounts, close dates and payout splits drift; manual line-by-line tie-out
A11: W1 | B11: meeting_notes/finance_review_2026-05-28.md | C11: 13 | D11: minutes (Maya Fortin) | E11: 46170 | F11: - Priya: this is now the single biggest finance time-sink and it's only going to get worse as brand-partnership volume grows. Flagged as the top candidate for fixing/automating — owner Maya to write up the current manual steps before we scope anything. | G11: CFO: single biggest finance time-sink; worse as volume grows; top automation candidate
A12: W1 | B12: meeting_notes/finance_review_2026-05-28.md | C12: 36 | D12: minutes (Maya Fortin) | E12: 46170 | F12: | 1 | Maya | Document current month-end brand-deal recon steps (CRM export + invoicing sheet + payout tracker) | Before June close | | G12: Action: Maya documents current recon steps before June close
A13: W1 | B13: meeting_notes/leadership_sync_2026-06-11.md | C13: 35 | D13: minutes (Marcus) | E13: 46184 | F13: - Priya raised that month-end brand-deal revenue reconciliation is eating ~3 days of Maya's time every month and never ties out first pass. Flagged as a candidate for the ops/automation review Marcus is running. No decision today. | G13: Leadership: ~3 days/month, flagged for Marcus's ops/automation review
A14: W1 | B14: pnl_q1_2026.csv | C14: 2 | F14: Revenue,Brand partnerships,4200000,Net of agency commissions | G14: Brand partnerships revenue $4.2M (Q1)
A15: W1 | B15: pnl_q1_2026.csv | C15: 5 | F15: Revenue,Total Revenue,5250000,Sum of revenue lines | G15: Total revenue $5.25M (Q1)
A16: W2 | B16: slack_export.md | C16: 171 | D16: Liam Doyle | E16: 46140 | F16: Adds up though. And tax form chasing is the other one — W-9s and W-8s for new creators, constant follow-up to get them returned. | G16: Tax-form chasing for new creators, constant follow-up
A17: W2 | B17: slack_export.md | C17: 176 | D17: Liam Doyle | E17: 46148 | F17: Honestly support is drowning. It's easily 40 hrs/week on creator support between the thumbnail swaps, the tax forms, and general "where's my payout" questions. We need help here. | G17: Ops: 'easily 40 hrs/week' across thumbnails, tax forms, payout questions
A18: W2 | B18: slack_export.md | C18: 201 | D18: Liam Doyle | E18: 46177 | F18: Tax form season again, chasing W-8s from the international creators. Manual every time. Anyone got a tool rec? | G18: 'Tax form season again'; W-8 chasing; manual; asks for a tool
A19: W2 | B19: slack_export.md | C19: 204 | D19: Elena Novak | E19: 46177 | F19: There are e-sign + tax form services. Cheap. Let's revisit in Q3 planning. | G19: People: e-sign + tax form services are 'cheap'; revisit Q3
A20: W3 | B20: slack_export.md | C20: 165 | D20: Liam Doyle | E20: 46140 | F20: Ops standup notes: thumbnail re-upload requests are piling up again. Creators want swaps after publish and it's all manual through the CMS. Volume is high. | G20: Thumbnail swaps piling up; all manual through the CMS
A21: W3 | B21: slack_export.md | C21: 168 | D21: Yuki Tanaka | E21: 46140 | F21: Post team feels it too. Every swap is a manual re-export and re-upload. Annoying but each one's only a few minutes. | G21: Post: each swap is a manual re-export, 'only a few minutes' (log says ~22 min)
A22: W3 | B22: slack_export.md | C22: 193 | D22: Liam Doyle | E22: 46163 | F22: Thumbnail swap request #47 this week. I'm not exaggerating about the volume. If we automated self-serve thumbnail replacement half my tickets would vanish. | G22: '#47 this week'; self-serve would make 'half my tickets' vanish
A23: W3 | B23: slack_export.md | C23: 196 | D23: Yuki Tanaka | E23: 46163 | F23: Worth scoping. Low dollar value per ticket but high annoyance. | G23: Content: worth scoping; low $ per ticket, high annoyance
A24: W4 | B24: slack_export.md | C24: 176 | D24: Liam Doyle | E24: 46148 | F24: Honestly support is drowning. It's easily 40 hrs/week on creator support between the thumbnail swaps, the tax forms, and general "where's my payout" questions. We need help here. | G24: Ops: 'easily 40 hrs/week' across thumbnails, tax forms, payout questions
A25: W4 | B25: slack_export.md | C25: 100 | D25: Maya Fortin | E25: 46134 | F25: For the record the three are: the CRM export (what Sales says closed), the invoicing sheet (what we billed), and the payout tracker (what creators actually got paid against deals). They drift every single month. | G25: Names the 3 sources: CRM export, invoicing sheet, payout tracker; 'drift every single month'
A26: W4 | B26: pnl_q1_2026.csv | C26: 34 | F26: G&A,Bank & payment processing fees,31000,Creator payouts processing | G26: Payout processing fees $31k (Q1)
A27: W6 | B27: slack_export.md | C27: 53 | D27: Ben Okoro | E27: 46170 | F27: Heads up: the "active creators" number is going to look different depending on who you ask. Data defines it as posted-in-last-30-days. Finance is using roster-under-contract. They're not the same population and people keep using them interchangeably in decks. | G27: 'Active creators' means different things to Data vs Finance
A28: W6 | B28: slack_export.md | C28: 59 | D28: Ben Okoro | E28: 46170 | F28: We can, but it's a real definitional choice, not a typo. They measure different things. I'd rather you tell me which one you want as the headline than me just picking. | G28: It's a definitional choice, not a typo
A29: W6 | B29: slack_export.md | C29: 130 | D29: Maya Fortin | E29: 46164 | F29: Quick one for the board cut — when we say "active roster," I'm using 1,840 creators under contract. That's the number Sofia's team gave me for creators we have signed agreements with. | G29: Finance uses 1,840 under contract as 'active roster'
A30: W6 | B30: slack_export.md | C30: 136 | D30: Ben Okoro | E30: 46164 | F30: Just flagging again — that's not the same as "active." Data's active-creator number (posted at least once in the last 30 days) is 1,210. Different definition, different population. As long as the deck labels which one it is, fine. They keep getting mixed up. | G30: Data's active = 1,210; keep getting mixed up
A31: W6 | B31: meeting_notes/data_review_2026-05-20.md | C31: 13 | D31: minutes (Ben Okoro) | E31: 46162 | F31: > **Data team definition of "active":** a creator who **posted ≥1 time in the last 30 days**. | G31: Data definition: posted ≥1 in 30 days = 1,210
A32: W6 | B32: meeting_notes/data_review_2026-05-20.md | C32: 16 | D32: minutes (Ben Okoro) | E32: 46162 | F32: Ben flagged that this is *not* the same as the headcount Finance and Talent quote. Finance/Talent talk about "creators under contract" (the signed roster), which is a larger number and counts everyone with an active agreement regardless of whether they posted. The Data dashboard intentionally measures **engagement**, not the contract book. | G32: Finance/Talent count the signed roster — larger number
A33: W6 | B33: meeting_notes/data_review_2026-05-20.md | C33: 18 | D33: minutes (Ben Okoro) | E33: 46162 | F33: - Dana: wants the two reconciled before the board update — "I don't want to say 1,210 in one slide and a different number in another." | G33: CEO wants them reconciled before the board update
A34: W6 | B34: meeting_notes/finance_review_2026-05-28.md | C34: 18 | D34: minutes (Maya Fortin) | E34: 46170 | F34: - Finance is modeling subscription and management economics against the **active roster of 1,840 creators under contract**. Priya wants the per-creator contribution view built off that 1,840 base for the board deck. | G34: Finance models per-creator economics on 1,840
A35: W6 | B35: meeting_notes/finance_review_2026-05-28.md | C35: 19 | D35: minutes (Maya Fortin) | E35: 46170 | F35: - Dana asked whether 1,840 is the right denominator — Maya to confirm with Data, since marketing/data have been quoting a different engagement-based number. Parked for now; finance continues on 1,840 under contract. | G35: CEO questions the denominator; parked
A36: W6 | B36: meeting_notes/leadership_sync_2026-06-11.md | C36: 30 | D36: minutes (Marcus) | E36: 46184 | F36: - Recurring confusion on the headline creator number — Ben (Data) reports **1,210 active** (posted ≥1x in last 30 days), Finance reports **1,840 under contract**. Two different definitions, not reconciled. | G36: Recurring confusion: 1,210 vs 1,840, not reconciled
A37: W6 | B37: meeting_notes/leadership_sync_2026-06-11.md | C37: 31 | D37: minutes (Marcus) | E37: 46184 | F37: - Dana: pick ONE headline definition before the board update. **Action: Priya + Ben to agree a single definition and label, by next sync.** | G37: Action: pick one definition before the board update
A38: W7 | B38: slack_export.md | C38: 34 | D38: Yuki Tanaka | E38: 46142 | F38: Production throughput was strong in Q1 — most shows shipped on schedule. The bottleneck is post, not shooting. Flagging for the ops conversation. | G38: Bottleneck is post, not shooting
... A40: W7 | B40: slack_export.md | C40: 250 | D40: Yuki Tanaka | E40: 46188 | F40: Post production could use another editor — that's the real bottleneck, not shooting. Will submit. | G40: Post needs another editor — the real bottleneck
A41: W7 | B41: pnl_q1_2026.csv | C41: 8 | F41: Personnel,Contractor / freelance production,410000,Variable production crews | G41: Contractor / freelance production $410k (Q1)
...

Sheet Tickets (raw)
A1: Raw export: support_tickets_q1_2026.csv — all 140 rows, unchanged. Used for the measured support hours.
A2: Source line | B2: Ticket_ID | C2: Date | D2: Category | E2: Submitted_By | F2: Assigned_To | G2: Handle_Minutes | H2: Status
A3: 2 | B3: TCK-1001 | C3: 46024 | D3: Thumbnail re-upload | E3: creator_avaloncreates | F3: Ops Support | G3: 25 | H3: Closed
A4: 3 | B4: TCK-1002 | C4: 46024 | D4: Tax form (W-9/W-8) | E4: creator_brightpixel | F4: Ops Support | G4: 50 | H4: Closed
A5: 4 | B5: TCK-1003 | C5: 46025 | D5: Login issue | E5: creator_chartedwaters | F5: Ops Support | G5: 15 | H5: Closed
A6: 5 | B6: TCK-1004 | C6: 46025 | D6: Thumbnail re-upload | E6: creator_dunemotion | F6: Ops Support | G6: 20 | H6: Closed
A7: 6 | B7: TCK-1005 | C7: 46027 | D7: Payout question | E7: creator_emberlite | F7: Ops Support | G7: 55 | H7: Closed
A8: 7 | B8: TCK-1006 | C8: 46027 | D8: Tax form (W-9/W-8) | E8: creator_foxglovestudio | F8: Ops Support | G8: 45 | H8: Closed
A9: 8 | B9: TCK-1007 | C9: 46028 | D9: Thumbnail re-upload | E9: creator_glasscanyon | F9: Ops Support | G9: 25 | H9: Closed
A10: 9 | B10: TCK-1008 | C10: 46028 | D10: Thumbnail re-upload | E10: creator_harborlight | F10: Ops Support | G10: 20 | H10: Closed
A11: 10 | B11: TCK-1009 | C11: 46029 | D11: Tax form (W-9/W-8) | E11: creator_ivoryreef | F11: Ops Support | G11: 45 | H11: Closed
A12: 11 | B12: TCK-1010 | C12: 46029 | D12: Login issue | E12: creator_junipertrail | F12: Ops Support | G12: 10 | H12: Closed
A13: 12 | B13: TCK-1011 | C13: 46030 | D13: Thumbnail re-upload | E13: creator_kelpforest | F13: Ops Support | G13: 25 | H13: Closed
A14: 13 | B14: TCK-1012 | C14: 46030 | D14: Payout question | E14: creator_lanternbay | F14: Ops Support | G14: 50 | H14: Closed
A15: 14 | B15: TCK-1013 | C15: 46031 | D15: Tax form (W-9/W-8) | E15: creator_moonlitpath | G15: 45 | H15: Closed
A16: 15 | B16: TCK-1014 | C16: 46031 | D16: Thumbnail re-upload | E16: creator_northstarvideo | F16: Ops Support | G16: 20 | H16: Closed
A17: 16 | B17: TCK-1015 | C17: 46034 | D17: Thumbnail re-upload | E17: creator_oakhollow | F17: Ops Support | G17: 25 | H17: Closed
A18: 17 | B18: TCK-1016 | C18: 46034 | D18: Account access | E18: creator_pinegrove | F18: Ops Support | G18: 25 | H18: Closed
A19: 18 | B19: TCK-1017 | C19: 46035 | D19: Tax form (W-9/W-8) | E19: creator_quietharbor | F19: Ops Support | G19: 40 | H19: Closed
A20: 19 | B20: TCK-1018 | C20: 46035 | D20: Thumbnail re-upload | E20: creator_riverstone | F20: Ops Support | G20: 20 | H20: Closed
A21: 20 | B21: TCK-1019 | C21: 46036 | D21: Payout question | E21: creator_silvercrest | F21: Ops Support | G21: 45 | H21: Closed
A22: 21 | B22: TCK-1020 | C22: 46036 | D22: Thumbnail re-upload | E22: creator_tidalwave | F22: Ops Support | G22: 25 | H22: Closed
A23: 22 | B23: TCK-1021 | C23: 46037 | D23: Tax form (W-9/W-8) | E23: creator_umberglow | F23: Ops Support | G23: 50 | H23: Closed
A24: 23 | B24: TCK-1022 | C24: 46037 | D24: Login issue | E24: creator_violetdusk | F24: Ops Support | G24: 10 | H24: Closed
A25: 24 | B25: TCK-1023 | C25: 46038 | D25: Thumbnail re-upload | E25: creator_wildfern | F25: Ops Support | G25: 20 | H25: Closed
A26: 25 | B26: TCK-1024 | C26: 46038 | D26: Thumbnail re-upload | E26: creator_xanaduclips | F26: Ops Support | G26: 25 | H26: Closed
A27: 26 | B27: TCK-1025 | C27: 46041 | D27: Tax form (W-9/W-8) | E27: creator_yellowpine | F27: Ops Support | G27: 45 | H27: Closed
... A39: 38 | B39: TCK-1037 | C39: 46049 | D39: Tax form (W-9/W-8) | E39: creator_larkspur | F39: Ops Support | G39: 45 | H39: Closed
A40: 39 | B40: TCK-1038 | C40: 46049 | D40: Thumbnail re-upload | E40: creator_mistralwind | G40: 25 | H40: Closed
A41: 40 | B41: TCK-1039 | C41: 46050 | D41: Account access | E41: creator_nightowl | F41: Ops Support | G41: 20 | H41: Closed
A42: 41 | B42: TCK-1040 | C42: 46050 | D42: Thumbnail re-upload | E42: creator_opalbeach | F42: Ops Support | G42: 25 | H42: Closed
A43: 42 | B43: TCK-1041 | C43: 46051 | D43: Tax form (W-9/W-8) | E43: creator_pebblecreek | F43: Ops Support | G43: 40 | H43: Closed
A44: 43 | B44: TCK-1042 | C44: 46051 | D44: Thumbnail re-upload | E44: creator_quillfeather | F44: Ops Support | G44: 20 | H44: Closed
A45: 44 | B45: TCK-1043 | C45: 46052 | D45: Payout question | E45: creator_redwoodway | F45: Ops Support | G45: 50 | H45: Closed
A46: 45 | B46: TCK-1044 | C46: 46052 | D46: Thumbnail re-upload | E46: creator_sanddollar | F46: Ops Support | G46: 25 | H46: Closed
A47: 46 | B47: TCK-1045 | C47: 46055 | D47: Tax form (W-9/W-8) | E47: creator_thornbush | F47: Ops Support | G47: 45 | H47: Closed
A48: 47 | B48: TCK-1046 | C48: 46055 | D48: Thumbnail re-upload | E48: creator_underbrush | F48: Ops Support | G48: 20 | H48: Closed
A49: 48 | B49: TCK-1047 | C49: 46056 | D49: Login issue | E49: creator_vellichor | F49: Ops Support | G49: 10 | H49: Closed
A50: 49 | B50: TCK-1048 | C50: 46056 | D50: Thumbnail re-upload | E50: creator_windrose | F50: Ops Support | G50: 25 | H50: Closed
A51: 50 | B51: TCK-1049 | C51: 46057 | D51: Tax form (W-9/W-8) | E51: creator_xeriscape | F51: Ops Support | G51: 50 | H51: Closed
...

Sheet Missing data
A1: What isn't in the bundle — and who can unblock it.
A2: Workflow | B2: Missing | C2: What it would settle | D2: Who
A3: W1 | B3: CRM deal export, invoicing sheet, payout tracker | C3: Can't build or test the recon automation; can't measure real recon time | D3: Maya Fortin / Finance
A4: W1 | B4: Maya's written-up recon steps (finance_review L36, due before June close) | C4: Exact scope and edge cases of the automation | D4: Maya Fortin
A5: W1 | B5: Time log for the recon | C5: Turns '~3 days' into a measured number (bounds 45–84 h/qtr) | D5: 2-month time log
A6: W2–W5 | B6: Q2 support tickets | C6: Tests Ops' May '#47 this week' surge | D6: Ben Okoro (Data)
A7: W2 | B7: E-sign / tax-form service quotes | C7: Cost side of the business case (break-even ≈ $2.1k/yr on time alone) | D7: Elena Novak (People)
A8: W3 | B8: Engineering estimate for self-serve thumbnail swap; CMS cost | C8: Cost side (break-even ≈ $1.8k/yr on time alone) | D8: Raj Patel (Eng)
A9: W6 | B9: Agreed headline definition of 'active creators' | C9: Removes recurring deck rework | D9: Priya + Ben (leadership L31)
A10: W7 | B10: Post-production throughput / backlog data | C10: Sizes the content bottleneck | D10: Yuki Tanaka
A11: W8 | B11: Vendor invoices / contracts | C11: Confirms Amplitude duplicate, Salesforce posting | D11: AP / Maya
